Workbook

Sheet Env-bk
A1: Test Environment
A2: HW | B2: Host | C2: dbgsz11
B3: Board | C3: xFusion #2
B4: xFusion MLB s/n | C4: 02YACYLHS3000001
B5: BMC MLB SN | C5: 02YABSXFR90008(old)
B6: CPU QDF | C6: CPU DMR-AP1/A0 X1/ES1/Q9WK
B7: CPU NO. | C7: R-U03383
B8: CPU SN | C8: D5US998200043
B9: CPU PPIN | C9: 5795964AD7886700
B10: CX8 SN | C10: MT2529J01M5T
B11: RISER SN | C11: 02YAVXFS2000010
B12: PDB | C12: ?
B13: MCIO cable 1 | C13: ?
B14: MCIO cable 2 | C14: ?
... B21: XDP | C21: F2221398
A22: SW | B22: BIOS ID | C22: OKSDCRB1.IPC.0032.D91.2604210616
B23: recipe_version | C23: PCIE.001.000.MAIN.Ax
B24: firmware_version | C24: 25WW36.3.AxBx'
B25: CX8 FW | C25: ?
B26: mainboard CPLD | C26: 0.07
B27: mainboard VRD | C27: 1
B28: BMC Firmwarm | C28: 3.09.02.06
B29: MMC firmware version | C29: 0.770.0 (0x00030200)
B30: Pythonsv | C30: Python3.10.9
B31: Memtest86 Ver | C31: MemTest86 V11.6 Pro (64-bit)/USB:

Sheet Env
A1: PCIe NTA system config2 | B1: dbgsz11
A2: Compoment | B2: Version | C2: Quantity | D2: SN
A3: BIOS | B3: OKSDCRB1.IPC.0032.D91.2604210616
A4: Recipe | B4: /
A5: CPLD FW | B5: 0.07
A6: BMC FW | B6: 3.09.02.06
A7: CX8 FW | C7: 1 | D7: MT2529J01M5T
A8: CPU | B8: Q9WK | C8: 1 | D8: R-U03383
A9: MB | B9: 2188H V9 | C9: 1 | D9: 02YACYLHS3000001
A10: DC-SCM | B10: / | C10: 1 | D10: 02YABSXFR90008
A11: PDB | B11: /
A12: Riser card | B12: / | C12: 1 | D12: 02YAVXFS2000010/02YAVXFR90000008
A13: MCIO cable 1 | B13: /
A14: MCIO cable 2 | B14: /
A15: MT cable | B15: /
A16: MT board | B16: /
A17: PSU | B17: / | D17: 210231YDAT
A18: HPM Power Cable | B18: /
A19: HPM Power Board | B19: /
A20: CX8 NTA test card | B20: /
A21: DIMM | B21: SAMSUNG 32G 2RX8 6400 1DCP | D21: SAMSUNG 32G 2RX8 6400 1DCP
A22: XDP | B22: / | D22: F2221398

Sheet Summary
A1: Machine | B1: Test Owner | C1: Project Name | D1: CPU/QDF | E1: DIMM Group | F1: pxpstr.portstr_width | G1: LTSSM | I1: SMV_Margin | K1: Note
G2: GEN6 | H2: GEN5 | I2: GEN6 | J2: GEN5
A3: dbgsz11 | B3: name | C3: Board | D3: stage | E3: DIMM Group | G3: Execution Rate
A4: xFusion #2 | B4: Huang, Qian | C4: 02YACYLHS3000001 | D4: ES1/Q9WK | E4: SAMSUNG 32G 2RX8 6400 1DPC | F4: pxp1.port0_x8 | G4: 1 | H4: 1 | I4: 1 | J4: 1 | K4: No Blocking Cases
A5: xFusion #2 | B5: Huang, Qian | C5: 02YACYLHS3000001 | D5: ES1/Q9WK | E5: SAMSUNG 32G 2RX8 6400 1DPC | F5: pxp1.port4_x8 | G5: 1 | H5: 1 | I5: 1 | J5: 1 | K5: No Blocking Cases
A6: xFusion #2 | B6: Huang, Qian | C6: 02YACYLHS3000001 | D6: ES1/Q9WK | E6: SAMSUNG 32G 2RX8 6400 1DPC | F6: pxp3.port0_x16 | G6: 1 | H6: 1 | I6: 1 | J6: 1 | K6: No Blocking Cases
A7: xFusion #2 | B7: Huang, Qian | C7: 02YACYLHS3000001 | D7: ES1/Q9WK | E7: SAMSUNG 32G 2RX8 6400 1DPC | F7: pxp4.port0_x8 | G7: 1 | H7: 1 | I7: 1 | J7: 1 | K7: No Blocking Cases
A8: xFusion #2 | B8: Huang, Qian | C8: 02YACYLHS3000001 | D8: ES1/Q9WK | E8: SAMSUNG 32G 2RX8 6400 1DPC | F8: pxp4.port4_x8 | G8: 1 | H8: 1 | I8: 1 | J8: 1 | K8: No Blocking Cases
A9: xFusion #2 | B9: Huang, Qian | C9: 02YACYLHS3000001 | D9: ES1/Q9WK | E9: SAMSUNG 32G 2RX8 6400 1DPC | F9: pxp9.port0_x16 | G9: 1 | H9: 1 | I9: 1 | J9: 1 | K9: No Blocking Cases
A10: xFusion #2 | B10: Huang, Qian | C10: 02YACYLHS3000001 | D10: ES1/Q9WK | E10: SAMSUNG 32G 2RX8 6400 1DPC | F10: pxp11.port0_x16 | G10: 1 | H10: 1 | I10: 1 | J10: 1 | K10: No Blocking Cases
A11: xFusion #2 | B11: Huang, Qian | C11: 02YACYLHS3000001 | D11: ES1/Q9WK | E11: SAMSUNG 32G 2RX8 6400 1DPC | F11: pxp12.port0_x16 | G11: 1 | H11: 1 | I11: 1 | J11: 1 | K11: No Blocking Cases
A13: Machine | B13: Test Owner | C13: Project Name | D13: CPU/QDF | E13: DIMM Group | F13: Bifurcation | G13: LTSSM | I13: SMV_Margin | K13: Note
G14: GEN6 | H14: GEN5 | I14: GEN6 | J14: GEN5
A15: dbgsz11 | B15: name | C15: Board | D15: stage | E15: DIMM Group | G15: Pass Rate
A16: xFusion #2 | B16: Huang, Qian | C16: 02YACYLHS3000001 | D16: ES1/Q9WK | E16: SAMSUNG 32G 2RX8 6400 1DPC | F16: pxp1.port0_x8 | G16: 0.875 | H16: 1 | I16: 1 | J16: 1 | K16: link_disable: Dev 0.pxp1.port0 is in DL_Down after test!
A17: xFusion #2 | B17: Huang, Qian | C17: 02YACYLHS3000001 | D17: ES1/Q9WK | E17: SAMSUNG 32G 2RX8 6400 1DPC | F17: pxp1.port4_x8 | G17: 0.875 | H17: 1 | I17: 1 | J17: 1 | K17: link_disable: Dev 0.pxp1.port4 is in DL_Down after test!
A18: xFusion #2 | B18: Huang, Qian | C18: 02YACYLHS3000001 | D18: ES1/Q9WK | E18: SAMSUNG 32G 2RX8 6400 1DPC | F18: pxp3.port0_x16 | G18: 1 | H18: 1 | I18: 1 | J18: 1
A19: xFusion #2 | B19: Huang, Qian | C19: 02YACYLHS3000001 | D19: ES1/Q9WK | E19: SAMSUNG 32G 2RX8 6400 1DPC | F19: pxp4.port0_x8 | G19: 0.875 | H19: 1 | I19: 1 | J19: 1 | K19: link_disable: Dev 0.pxp4.port0 is in DL_Down after test!
A20: xFusion #2 | B20: Huang, Qian | C20: 02YACYLHS3000001 | D20: ES1/Q9WK | E20: SAMSUNG 32G 2RX8 6400 1DPC | F20: pxp4.port4_x8 | G20: 0.875 | H20: 1 | I20: 1 | J20: 1 | K20: link_disable: Dev 0.pxp4.port4 is in DL_Down after test!
A21: xFusion #2 | B21: Huang, Qian | C21: 02YACYLHS3000001 | D21: ES1/Q9WK | E21: SAMSUNG 32G 2RX8 6400 1DPC | F21: pxp9.port0_x16 | G21: 1 | H21: 1 | I21: 1 | J21: 1
A22: xFusion #2 | B22: Huang, Qian | C22: 02YACYLHS3000001 | D22: ES1/Q9WK | E22: SAMSUNG 32G 2RX8 6400 1DPC | F22: pxp11.port0_x16 | G22: 1 | H22: 1 | I22: 1 | J22: 1
A23: xFusion #2 | B23: Huang, Qian | C23: 02YACYLHS3000001 | D23: ES1/Q9WK | E23: SAMSUNG 32G 2RX8 6400 1DPC | F23: pxp12.port0_x16 | G23: 1 | H23: 1 | I23: 1 | J23: 1
A25: Machine | B25: Test Owner | C25: Project Name | D25: CPU/QDF | E25: DIMM Group | F25: PCIE Port | G25: Test Case Number | H25: Pass | I25: Fail | J25: Block | K25: Execution Rate | L25: Pass Rate
A26: xFusion #2 | B26: Huang, Qian | C26: 02YACYLHS3000001 | D26: ES1/Q9WK | E26: SAMSUNG 32G 2RX8 6400 1DPC | F26: pxp1.port0_x8 | G26: 18 | H26: 17 | I26: 1 | J26: =G26-H26-I26 | K26: 1 | L26: =H26/G26
A27: xFusion #2 | B27: Huang, Qian | C27: 02YACYLHS3000001 | D27: ES1/Q9WK | E27: SAMSUNG 32G 2RX8 6400 1DPC | F27: pxp1.port4_x8 | G27: 18 | H27: 17 | I27: 1 | J27: =G27-H27-I27 | K27: 1 | L27: =H27/G27
A28: xFusion #2 | B28: Huang, Qian | C28: 02YACYLHS3000001 | D28: ES1/Q9WK | E28: SAMSUNG 32G 2RX8 6400 1DPC | F28: pxp3.port0_x16 | G28: 18 | H28: 18 | I28: 0 | J28: =G28-H28-I28 | K28: 1 | L28: =H28/G28
A29: xFusion #2 | B29: Huang, Qian | C29: 02YACYLHS3000001 | D29: ES1/Q9WK | E29: SAMSUNG 32G 2RX8 6400 1DPC | F29: pxp4.port0_x8 | G29: 18 | H29: 17 | I29: 1 | J29: =G29-H29-I29 | K29: 1 | L29: =H29/G29
A30: xFusion #2 | B30: Huang, Qian | C30: 02YACYLHS3000001 | D30: ES1/Q9WK | E30: SAMSUNG 32G 2RX8 6400 1DPC | F30: pxp4.port4_x8 | G30: 18 | H30: 17 | I30: 1 | J30: =G30-H30-I30 | K30: 1 | L30: =H30/G30
A31: xFusion #2 | B31: Huang, Qian | C31: 02YACYLHS3000001 | D31: ES1/Q9WK | E31: SAMSUNG 32G 2RX8 6400 1DPC | F31: pxp9.port0_x16 | G31: 18 | H31: 18 | I31: 0 | J31: =G31-H31-I31 | K31: 1 | L31: =H31/G31
A32: xFusion #2 | B32: Huang, Qian | C32: 02YACYLHS3000001 | D32: ES1/Q9WK | E32: SAMSUNG 32G 2RX8 6400 1DPC | F32: pxp11.port0_x16 | G32: 18 | H32: 18 | I32: 0 | J32: =G32-H32-I32 | K32: 1 | L32: =H32/G32
A33: xFusion #2 | B33: Huang, Qian | C33: 02YACYLHS3000001 | D33: ES1/Q9WK | E33: SAMSUNG 32G 2RX8 6400 1DPC | F33: pxp12.port0_x16 | G33: 18 | H33: 18 | I33: 0 | J33: =G33-H33-I33 | K33: 1 | L33: =H33/G33
A34: Overal Summary | G34: =SUM(G26:G33) | H34: =SUM(H26:H33) | I34: =SUM(I26:I33) | J34: =SUM(J26:J33) | K34: 1 | L34: 0.5

Sheet Test_Details_bk
A1: 原始序列 | B1: ID | C1: 父 ID | D1: Level | E1: Date | F1: Board | G1: Board Name | H1: PPIN | I1: QDF | J1: Memory P/N | K1: BIOS | L1: Port | M1: Gen# | N1: WO# | O1: Test | P1: Additional BIOS Settings | Q1: iteration | R1: reset | S1: resetType | T1: Time | U1: Result | V1: Failed iterations | W1: Fail rate | X1: Symptoms | Y1: Status | Z1: Reason_other | AA1: HSD# | AB1: Log Link | AC1: Comments
A2: 1 | B2: 1L1 | C2: 0 | D2: =IF(C2=0,1,2) | E2: 46125 | F2: Intel JNC2 | G2: VAO254600036 | H2: 5772954CF1246B4E | I2: ES1/Q9WJ | J2: M321R4GA3PB1-CCPPC 00CE012332050091C9 | K2: 32D91 | L2: pxp1 | M2: Gen6 | O2: LTSSM | P2: NA | Q2: 1000 | R2: NA | S2: NA | T2: 0.18084491 | U2: Pass | W2: 0
A3: 2 | B3: 1S1 | C3: 0 | D3: =IF(C3=0,1,2) | F3: Intel JNC2 | G3: VAO254600036 | H3: 5772954CF1246B4E | I3: ES1/Q9WJ | J3: M321R4GA3PB1-CCPPC 00CE012332050091C9 | K3: 32D91 | L3: pxp1 | M3: Gen6 | O3: SMV_Margin | P3: NA | Q3: 3 | R3: 3 | S3: 3 | T3: 0.047372685 | U3: Pass
A4: 3 | B4: 1L3 | C4: 0 | D4: =IF(C4=0,1,2) | E4: 46125 | F4: Intel JNC2 | G4: VAO254600036 | H4: 5772954CF1246B4E | I4: ES1/Q9WJ | J4: M321R4GA3PB1-CCPPC 00CE012332050091C9 | K4: 32D91 | L4: pxp3 | M4: Gen6 | O4: LTSSM | P4: NA | Q4: 1000 | R4: NA | S4: NA | T4: 0.18145833 | U4: Pass | W4: 0
A5: 4 | B5: 1S3 | C5: 0 | D5: =IF(C5=0,1,2) | F5: Intel JNC2 | G5: VAO254600036 | H5: 5772954CF1246B4E | I5: ES1/Q9WJ | J5: M321R4GA3PB1-CCPPC 00CE012332050091C9 | K5: 32D91 | L5: pxp3 | M5: Gen6 | O5: SMV_Margin | P5: NA | Q5: 3 | R5: 3 | S5: 3 | T5: 0.047222222 | U5: Pass
A6: 5 | B6: 1L4 | C6: 0 | D6: =IF(C6=0,1,2) | F6: Intel JNC2 | G6: VAO254600036 | H6: 5772954CF1246B4E | I6: ES1/Q9WJ | J6: M321R4GA3PB1-CCPPC 00CE012332050091C9 | K6: 32D91 | L6: pxp4 | M6: Gen6 | O6: LTSSM | P6: NA | Q6: 1000 | R6: NA | S6: NA | T6: 0.18545139 | U6: Pass | W6: 0
A7: 6 | B7: 1S4 | C7: 0 | D7: =IF(C7=0,1,2) | F7: Intel JNC2 | G7: VAO254600036 | H7: 5772954CF1246B4E | I7: ES1/Q9WJ | J7: M321R4GA3PB1-CCPPC 00CE012332050091C9 | K7: 32D91 | L7: pxp4 | M7: Gen6 | O7: SMV_Margin | P7: NA | Q7: 3 | R7: 3 | S7: 3 | T7: 0.047280093 | U7: Pass
A8: 7 | B8: 1L9 | C8: 0 | D8: =IF(C8=0,1,2) | E8: 46125 | F8: Intel JNC2 | G8: VAO254600036 | H8: 5772954CF1246B4E | I8: ES1/Q9WJ | J8: M321R4GA3PB1-CCPPC 00CE012332050091C9 | K8: 32D91 | L8: pxp9 | M8: Gen6 | O8: LTSSM | P8: NA | Q8: 1000 | R8: NA | S8: NA | T8: 0.24822917 | U8: Pass | W8: 0
A9: 8 | B9: 1S9 | C9: 0 | D9: =IF(C9=0,1,2) | F9: Intel JNC2 | G9: VAO254600036 | H9: 5772954CF1246B4E | I9: ES1/Q9WJ | J9: M321R4GA3PB1-CCPPC 00CE012332050091C9 | K9: 32D91 | L9: pxp9 | M9: Gen6 | O9: SMV_Margin | P9: NA | Q9: 3 | R9: 3 | S9: 3 | T9: 0.047881944 | U9: Pass
A10: 9 | B10: 1L11 | C10: 0 | D10: =IF(C10=0,1,2) | F10: Intel JNC2 | G10: VAO254600036 | H10: 5772954CF1246B4E | I10: ES1/Q9WJ | J10: M321R4GA3PB1-CCPPC 00CE012332050091C9 | K10: 32D91 | L10: pxp11 | M10: Gen6 | O10: LTSSM | P10: NA | Q10: 1000 | R10: NA | S10: NA | T10: 0.2240162 | U10: Fail | V10: 189 | W10: 0.189 | X10: runSpeedChangeAll:uncorrectable errors
A11: 10 | B11: 1R11 | C11: 0 | D11: =IF(C11=0,1,2) | F11: Intel JNC2 | G11: VAO254600036 | H11: 5772954CF1246B4E | I11: ES1/Q9WJ | J11: M321R4GA3PB1-CCPPC 00CE012332050091C9 | K11: 32D91 | L11: pxp11 | M11: Gen6 | O11: SMV_Margin | P11: NA | Q11: 3 | R11: 3 | S11: 3 | T11: 0.04724537 | U11: Pass | AC11: runSpeedChangeAll:ocket 0, pxp11.port0 has detected uncorrectable errors
A12: 11 | B12: 1L12 | C12: 0 | D12: =IF(C12=0,1,2) | F12: Intel JNC2 | G12: VAO254600036 | H12: 5772954CF1246B4E | I12: ES1/Q9WJ | J12: M321R4GA3PB1-CCPPC 00CE012332050091C9 | K12: 32D91 | L12: pxp12 | M12: Gen6 | O12: LTSSM | P12: NA | Q12: 1000 | R12: NA | S12: NA
A13: 12 | B13: 1R12 | C13: 0 | D13: =IF(C13=0,1,2) | F13: Intel JNC2 | G13: VAO254600036 | H13: 5772954CF1246B4E | I13: ES1/Q9WJ | J13: M321R4GA3PB1-CCPPC 00CE012332050091C9 | K13: 32D91 | L13: pxp12 | M13: Gen6 | O13: SMV_Margin | P13: NA | Q13: 3 | R13: 3 | S13: 3
A14: 13 | B14: 2L1 | C14: 0 | D14: =IF(C14=0,1,2) | F14: Intel JNC2 | G14: VAO254600036 | H14: 5772954CF1246B4E | I14: ES1/Q9WJ | J14: M321R4GA3PB1-CCPPC 00CE012332050091C9 | K14: 32D91 | L14: pxp1 | M14: Gen5 | O14: LTSSM | P14: NA | Q14: 1000 | R14: NA | S14: NA | T14: 0.10194444 | U14: Fail | V14: 15 | W14: 0.0015 | X14: PML1:Correctable error | AC14: PML1:Checking port: 0.pxp1.port0 width: x0x10 speed: Gen5 Unexpected Recovery!(Socket 0 pxp1.port0) Expected 0 but saw 1 recoveries after test. Socket 0, pxp1.port0 has detected correctable errors
A15: 14 | B15: 2S1 | C15: 0 | D15: =IF(C15=0,1,2) | F15: Intel JNC2 | G15: VAO254600036 | H15: 5772954CF1246B4E | I15: ES1/Q9WJ | J15: M321R4GA3PB1-CCPPC 00CE012332050091C9 | K15: 32D91 | L15: pxp1 | M15: Gen5 | O15: SMV_Margin | P15: NA | Q15: 3 | R15: 2 | S15: 3
A16: 15 | B16: 2L3 | C16: 0 | D16: =IF(C16=0,1,2) | F16: Intel JNC2 | G16: VAO254600036 | H16: 5772954CF1246B4E | I16: ES1/Q9WJ | J16: M321R4GA3PB1-CCPPC 00CE012332050091C9 | K16: 32D91 | L16: pxp3 | M16: Gen5 | O16: LTSSM | P16: NA | Q16: 1000 | R16: NA | S16: NA | T16: 0.10179398 | U16: Pass | W16: 0
A17: 16 | B17: 2S3 | C17: 0 | D17: =IF(C17=0,1,2) | F17: Intel JNC2 | G17: VAO254600036 | H17: 5772954CF1246B4E | I17: ES1/Q9WJ | J17: M321R4GA3PB1-CCPPC 00CE012332050091C9 | K17: 32D91 | L17: pxp3 | M17: Gen5 | O17: SMV_Margin | P17: NA | Q17: 3 | R17: 2 | S17: 3
A18: 17 | B18: 2L4 | C18: 0 | D18: =IF(C18=0,1,2) | F18: Intel JNC2 | G18: VAO254600036 | H18: 5772954CF1246B4E | I18: ES1/Q9WJ | J18: M321R4GA3PB1-CCPPC 00CE012332050091C9 | K18: 32D91 | L18: pxp4 | M18: Gen5 | O18: LTSSM | P18: NA | Q18: 1000 | R18: NA | S18: NA
A19: 18 | B19: 2S4 | C19: 0 | D19: =IF(C19=0,1,2) | F19: Intel JNC2 | G19: VAO254600036 | H19: 5772954CF1246B4E | I19: ES1/Q9WJ | J19: M321R4GA3PB1-CCPPC 00CE012332050091C9 | K19: 32D91 | L19: pxp4 | M19: Gen5 | O19: SMV_Margin | P19: NA | Q19: 3 | R19: 2 | S19: 3 | T19: 0.0665625 | U19: Pass
A20: 19 | B20: 2L9 | C20: 0 | D20: =IF(C20=0,1,2) | F20: Intel JNC2 | G20: VAO254600036 | H20: 5772954CF1246B4E | I20: ES1/Q9WJ | J20: M321R4GA3PB1-CCPPC 00CE012332050091C9 | K20: 32D91 | L20: pxp9 | M20: Gen5 | O20: LTSSM | P20: NA | Q20: 1000 | R20: NA | S20: NA | T20: 0.13450231 | U20: Pass | W20: 0
A21: 20 | B21: 2S9 | C21: 0 | D21: =IF(C21=0,1,2) | F21: Intel JNC2 | G21: VAO254600036 | H21: 5772954CF1246B4E | I21: ES1/Q9WJ | J21: M321R4GA3PB1-CCPPC 00CE012332050091C9 | K21: 32D91 | L21: pxp9 | M21: Gen5 | O21: SMV_Margin | P21: NA | Q21: 3 | R21: 2 | S21: 3
A22: 21 | B22: 2L11 | C22: 0 | D22: =IF(C22=0,1,2) | F22: Intel JNC2 | G22: VAO254600036 | H22: 5772954CF1246B4E | I22: ES1/Q9WJ | J22: M321R4GA3PB1-CCPPC 00CE012332050091C9 | K22: 32D91 | L22: pxp11 | M22: Gen5 | O22: LTSSM | P22: NA | Q22: 1000 | R22: NA | S22: NA
A23: 22 | B23: 2R11 | C23: 0 | D23: =IF(C23=0,1,2) | F23: Intel JNC2 | G23: VAO254600036 | H23: 5772954CF1246B4E | I23: ES1/Q9WJ | J23: M321R4GA3PB1-CCPPC 00CE012332050091C9 | K23: 32D91 | L23: pxp11 | M23: Gen5 | O23: SMV_Margin | P23: NA | Q23: 3 | R23: 2 | S23: 3
A24: 23 | B24: 2L12 | C24: 0 | D24: =IF(C24=0,1,2) | F24: Intel JNC2 | G24: VAO254600036 | H24: 5772954CF1246B4E | I24: ES1/Q9WJ | J24: M321R4GA3PB1-CCPPC 00CE012332050091C9 | K24: 32D91 | L24: pxp12 | M24: Gen5 | O24: LTSSM | P24: NA | Q24: 1000 | R24: NA | S24: NA
A25: 24 | B25: 2R12 | C25: 0 | D25: =IF(C25=0,1,2) | F25: Intel JNC2 | G25: VAO254600036 | H25: 5772954CF1246B4E | I25: ES1/Q9WJ | J25: M321R4GA3PB1-CCPPC 00CE012332050091C9 | K25: 32D91 | L25: pxp12 | M25: Gen5 | O25: SMV_Margin | P25: NA | Q25: 3 | R25: 2 | S25: 3

Sheet Test_Details
A1: 原始序列 | B1: ID | C1: 父 ID | D1: Level | E1: Host | F1: Board | G1: xFusion MLB s/n | H1: BMC MLB SN | I1: CPU QDF | J1: CPU PPIN | K1: Alias | L1: DIMM Vendor | M1: DIMM RCD Vendor | N1: Memory P/N | O1: DIMM Type | P1: Config | Q1: BIOS | R1: CX8 SN | S1: Riser card | T1: Gen# | U1: Test | V1: Bifurcation | W1: PCIE | X1: Pxpstr | Y1: Portno | Z1: WO# | AA1: iteration | AB1: reset | AC1: resetType | AD1: Test Duration | AE1: Result/Margin | AF1: retrain | AG1: speedchange_all | AH1: speedchange_max | AI1: txeqredo | AJ1: pml1_disable | AK1: sbr | AL1: link_disable | AM1: pml1_enable | AN1: Pass Rate | AO1: Bug HSD# | AP1: Log Link | AQ1: Comments
A2: 1 | B2: 1L1 | C2: 0 | D2: =IF(C2=0,1,2) | E2: dbgsz11 | F2: xFusion #2 | G2: 02YACYLHS3000001 | H2: 02YABSXFR90008 | I2: ES1/Q9WK | J2: 5795964AD7886700 | L2: Samsung | M2: Rambus | N2: M321R4GA3PB1-CCPYC | O2: RE32 | P2: 1DPC 6400(16) | Q2: 32.D91.2604210616 | R2: MT2529J01M5T | S2: 02YAVXFS2000010 | T2: Gen6 | U2: LTSSM | V2: x8x8 | W2: CX8 | X2: pxp1 | Y2: 0 | Z2: 15019294522 | AA2: 1000 | AB2: NA | AC2: NA | AD2: =SUM(LTSSM_Stress!J2:J9)/60 | AE2: FAIL | AF2: PASS | AG2: PASS | AH2: PASS | AI2: PASS | AJ2: PASS | AK2: PASS | AL2: FAIL | AM2: PASS | AN2: 0.875 | AP2: http://10.239.81.58/Xeon/NTA/PCIE/xfusion/unit2-dbgsz11/pxp1.port0_x8/LTSSM/ | AQ2: link_disable: Dev 0.pxp1.port0 is in DL_Down after test!
A3: 2 | B3: 1L1 | C3: 0 | D3: =IF(C3=0,1,2) | E3: dbgsz11 | F3: xFusion #2 | G3: 02YACYLHS3000001 | H3: 02YABSXFR90008 | I3: ES1/Q9WK | J3: 5795964AD7886700 | L3: Samsung | M3: Rambus | N3: M321R4GA3PB1-CCPYC | O3: RE32 | P3: 1DPC 6400(16) | Q3: 32.D91.2604210616 | R3: MT2529J01M5T | S3: 02YAVXFS2000010 | T3: Gen6 | U3: LTSSM | V3: x8x8 | W3: CX8 | X3: pxp1 | Y3: 4 | Z3: 15019301806 | AA3: 1000 | AB3: NA | AC3: NA | AD3: =SUM(LTSSM_Stress!J10:J17)/60 | AE3: FAIL | AF3: PASS | AG3: PASS | AH3: PASS | AI3: PASS | AJ3: PASS | AK3: PASS | AL3: FAIL | AM3: PASS | AN3: 0.875 | AP3: http://10.239.81.58/Xeon/NTA/PCIE/xfusion/unit2-dbgsz11/pxp1.port4_x8/LTSSM/ | AQ3: link_disable: Dev 0.pxp1.port4 is in DL_Down after test!
A4: 3 | B4: 1L1 | C4: 0 | D4: =IF(C4=0,1,2) | E4: dbgsz11 | F4: xFusion #2 | G4: 02YACYLHS3000001 | H4: 02YABSXFR90008 | I4: ES1/Q9WK | J4: 5795964AD7886700 | L4: Samsung | M4: Rambus | N4: M321R4GA3PB1-CCPYC | O4: RE32 | P4: 1DPC 6400(16) | Q4: 32.D91.2604210616 | R4: MT2529J01M5T | S4: 02YAVXFS2000010/02YAVXFR90000008 | T4: Gen6 | U4: LTSSM | V4: x16 | W4: CX8 | X4: pxp3 | Y4: 0 | Z4: =HYPERLINK("https://hsdes.intel.com/resource/15019302276", "15019302276") | AA4: 1000 | AB4: NA | AC4: NA | AD4: =SUM(LTSSM_Stress!J18:J25)/60 | AE4: PASS | AF4: PASS | AG4: PASS | AH4: PASS | AI4: PASS | AJ4: PASS | AK4: PASS | AL4: PASS | AM4: PASS | AN4: 1 | AP4: http://10.239.81.58/Xeon/NTA/PCIE/xfusion/unit2-dbgsz11/pxp3.port0_x16/LTSSM/ | AQ4: LTSSM use 02YAVXFS2000010 SMV margin use 02YAVXFR90000008
A5: 4 | B5: 1L1 | C5: 0 | D5: =IF(C5=0,1,2) | E5: dbgsz11 | F5: xFusion #2 | G5: 02YACYLHS3000001 | H5: 02YABSXFR90008 | I5: ES1/Q9WK | J5: 5795964AD7886700 | L5: Samsung | M5: Rambus | N5: M321R4GA3PB1-CCPYC | O5: RE32 | P5: 1DPC 6400(16) | Q5: 32.D91.2604210616 | R5: MT2529J01M5T | S5: 02YAVXFS2000010 | T5: Gen6 | U5: LTSSM | V5: x8x8 | W5: CX8 | X5: pxp4 | Y5: 0 | Z5: =HYPERLINK("https://hsdes.intel.com/resource/15019304439", "15019304439") | AA5: 1000 | AB5: NA | AC5: NA | AD5: =SUM(LTSSM_Stress!J26:J33)/60 | AE5: FAIL | AF5: PASS | AG5: PASS | AH5: PASS | AI5: PASS | AJ5: PASS | AK5: PASS | AL5: FAIL | AM5: PASS | AN5: 0.875 | AP5: http://10.239.81.58/Xeon/NTA/PCIE/xfusion/unit2-dbgsz11/pxp4.port0_x8/LTSSM/ | AQ5: link_disable: Dev 0.pxp4.port0 is in DL_Down after test!
A6: 5 | B6: 1L1 | C6: 0 | D6: =IF(C6=0,1,2) | E6: dbgsz11 | F6: xFusion #2 | G6: 02YACYLHS3000001 | H6: 02YABSXFR90008 | I6: ES1/Q9WK | J6: 5795964AD7886700 | L6: Samsung | M6: Rambus | N6: M321R4GA3PB1-CCPYC | O6: RE32 | P6: 1DPC 6400(16) | Q6: 32.D91.2604210616 | R6: MT2529J01M5T | S6: 02YAVXFS2000010 | T6: Gen6 | U6: LTSSM | V6: x8x8 | W6: CX8 | X6: pxp4 | Y6: 4 | Z6: =HYPERLINK("https://hsdes.intel.com/resource/15019305682", "15019305682") | AA6: 1000 | AB6: NA | AC6: NA | AD6: =SUM(LTSSM_Stress!J34:J41)/60 | AE6: FAIL | AF6: PASS | AG6: PASS | AH6: PASS | AI6: PASS | AJ6: PASS | AK6: PASS | AL6: FAIL | AM6: PASS | AN6: 0.875 | AP6: http://10.239.81.58/Xeon/NTA/PCIE/xfusion/unit2-dbgsz11/pxp4.port4_x8/LTSSM/ | AQ6: link_disable: Dev 0.pxp4.port4 is in DL_Down after test!
A7: 6 | B7: 1L1 | C7: 0 | D7: =IF(C7=0,1,2) | E7: dbgsz11 | F7: xFusion #2 | G7: 02YACYLHS3000001 | H7: 02YABSXFR90008 | I7: ES1/Q9WK | J7: 5795964AD7886700 | L7: Samsung | M7: Rambus | N7: M321R4GA3PB1-CCPYC | O7: RE32 | P7: 1DPC 6400(16) | Q7: 32.D91.2604210616 | R7: MT2529J01M5T | S7: 02YAVXFR90000008 | T7: Gen6 | U7: LTSSM | V7: x16 | W7: CX8 | X7: pxp9 | Y7: 0 | Z7: =HYPERLINK("https://hsdes.intel.com/resource/15019305362", "15019305362") | AA7: 1000 | AB7: NA | AC7: NA | AD7: =SUM(LTSSM_Stress!J42:J49)/60 | AE7: PASS | AF7: PASS | AG7: PASS | AH7: PASS | AI7: PASS | AJ7: PASS | AK7: PASS | AL7: PASS | AM7: PASS | AN7: 1 | AP7: http://10.239.81.58/Xeon/NTA/PCIE/xfusion/unit2-dbgsz11/pxp9.port0_x16/LTSSM/
A8: 7 | B8: 1L1 | C8: 0 | D8: =IF(C8=0,1,2) | E8: dbgsz11 | F8: xFusion #2 | G8: 02YACYLHS3000001 | H8: 02YABSXFR90008 | I8: ES1/Q9WK | J8: 5795964AD7886700 | L8: Samsung | M8: Rambus | N8: M321R4GA3PB1-CCPYC | O8: RE32 | P8: 1DPC 6400(16) | Q8: 32.D91.2604210616 | R8: MT2529J01M5T | S8: 02YAVXFR90000008 | T8: Gen6 | U8: LTSSM | V8: x16 | W8: CX8 | X8: pxp11 | Y8: 0 | Z8: =HYPERLINK("https://hsdes.intel.com/resource/15019305353", "15019305353") | AA8: 1000 | AB8: NA | AC8: NA | AD8: =SUM(LTSSM_Stress!J50:J57)/60 | AE8: PASS | AF8: PASS | AG8: PASS | AH8: PASS | AI8: PASS | AJ8: PASS | AK8: PASS | AL8: PASS | AM8: PASS | AN8: 1 | AP8: http://10.239.81.58/Xeon/NTA/PCIE/xfusion/unit2-dbgsz11/pxp11.port0_x16/LTSSM/
A9: 8 | B9: 1L1 | C9: 0 | D9: =IF(C9=0,1,2) | E9: dbgsz11 | F9: xFusion #2 | G9: 02YACYLHS3000001 | H9: 02YABSXFR90008 | I9: ES1/Q9WK | J9: 5795964AD7886700 | L9: Samsung | M9: Rambus | N9: M321R4GA3PB1-CCPYC | O9: RE32 | P9: 1DPC 6400(16) | Q9: 32.D91.2604210616 | R9: MT2529J01M5T | S9: 02YAVXFR90000008 | T9: Gen6 | U9: LTSSM | V9: x16 | W9: CX8 | X9: pxp12 | Y9: 0 | Z9: =HYPERLINK("https://hsdes.intel.com/resource/15019305348", "15019305348") | AA9: 1000 | AB9: NA | AC9: NA | AD9: =SUM(LTSSM_Stress!J58:J65)/60 | AE9: PASS | AF9: PASS | AG9: PASS | AH9: PASS | AI9: PASS | AJ9: PASS | AK9: PASS | AL9: PASS | AM9: PASS | AN9: 1 | AP9: http://10.239.81.58/Xeon/NTA/PCIE/xfusion/unit2-dbgsz11/pxp12.port0_x16/LTSSM/
A10: 9 | B10: 1S1 | C10: 0 | D10: =IF(C10=0,1,2) | E10: dbgsz11 | F10: xFusion #2 | G10: 02YACYLHS3000001 | H10: 02YABSXFR90008 | I10: ES1/Q9WK | J10: 5795964AD7886700 | L10: Samsung | M10: Rambus | N10: M321R4GA3PB1-CCPYC | O10: RE32 | P10: 1DPC 6400(16) | Q10: 32.D91.2604210616 | R10: MT2529J01M5T | S10: 02YAVXFS2000010 | T10: Gen6 | U10: SMV_Margin | V10: x8x8 | W10: CX8 | X10: pxp1 | Y10: 0 | Z10: 15019294637 | AA10: 3 | AB10: 3 | AC10: 3 | AD10: =ROUND((VALUE(LEFT(SMV_Margin!G2,SEARCH(":",SMV_Margin!G2)-1)) + VALUE(MID(SMV_Margin!G2,SEARCH(":",SMV_Margin!G2)+1,2))/60 + VALUE(RIGHT(SMV_Margin!G2,2))/3600),2) | AE10: PASS | AF10: NA | AG10: NA | AH10: NA | AI10: NA | AJ10: NA | AK10: NA | AL10: NA | AM10: NA | AN10: 1 | AP10: http://10.239.81.58/Xeon/NTA/PCIE/xfusion/unit2-dbgsz11/pxp1.port0_x8/SMV/
A11: 10 | B11: 1S1 | C11: 0 | D11: =IF(C11=0,1,2) | E11: dbgsz11 | F11: xFusion #2 | G11: 02YACYLHS3000001 | H11: 02YABSXFR90008 | I11: ES1/Q9WK | J11: 5795964AD7886700 | L11: Samsung | M11: Rambus | N11: M321R4GA3PB1-CCPYC | O11: RE32 | P11: 1DPC 6400(16) | Q11: 32.D91.2604210616 | R11: MT2529J01M5T | S11: 02YAVXFS2000010 | T11: Gen6 | U11: SMV_Margin | V11: x8x8 | W11: CX8 | X11: pxp1 | Y11: 4 | Z11: 15019302214 | AA11: 3 | AB11: 3 | AC11: 3 | AD11: =ROUND((VALUE(LEFT(SMV_Margin!G3,SEARCH(":",SMV_Margin!G3)-1)) + VALUE(MID(SMV_Margin!G3,SEARCH(":",SMV_Margin!G3)+1,2))/60 + VALUE(RIGHT(SMV_Margin!G3,2))/3600),2) | AE11: PASS | AF11: NA | AG11: NA | AH11: NA | AI11: NA | AJ11: NA | AK11: NA | AL11: NA | AM11: NA | AN11: 1 | AP11: http://10.239.81.58/Xeon/NTA/PCIE/xfusion/unit2-dbgsz11/pxp1.port4_x8/SMV/
A12: 11 | B12: 1S1 | C12: 0 | D12: =IF(C12=0,1,2) | E12: dbgsz11 | F12: xFusion #2 | G12: 02YACYLHS3000001 | H12: 02YABSXFR90008 | I12: ES1/Q9WK | J12: 5795964AD7886700 | L12: Samsung | M12: Rambus | N12: M321R4GA3PB1-CCPYC | O12: RE32 | P12: 1DPC 6400(16) | Q12: 32.D91.2604210616 | R12: MT2529J01M5T | S12: 02YAVXFS2000010/02YAVXFR90000008 | T12: Gen6 | U12: SMV_Margin | V12: x16 | W12: CX8 | X12: pxp3 | Y12: 0 | Z12: =HYPERLINK("https://hsdes.intel.com/resource/15019302281", "15019302281") | AA12: 3 | AB12: 3 | AC12: 3 | AD12: =ROUND((VALUE(LEFT(SMV_Margin!G4,SEARCH(":",SMV_Margin!G4)-1)) + VALUE(MID(SMV_Margin!G4,SEARCH(":",SMV_Margin!G4)+1,2))/60 + VALUE(RIGHT(SMV_Margin!G4,2))/3600),2) | AE12: PASS | AF12: NA | AG12: NA | AH12: NA | AI12: NA | AJ12: NA | AK12: NA | AL12: NA | AM12: NA | AN12: 1 | AP12: http://10.239.81.58/Xeon/NTA/PCIE/xfusion/unit2-dbgsz11/pxp3.port0_x16/SMV/ | AQ12: LTSSM use 02YAVXFS2000010 SMV margin use 02YAVXFR90000008
A13: 12 | B13: 1S1 | C13: 0 | D13: =IF(C13=0,1,2) | E13: dbgsz11 | F13: xFusion #2 | G13: 02YACYLHS3000001 | H13: 02YABSXFR90008 | I13: ES1/Q9WK | J13: 5795964AD7886700 | L13: Samsung | M13: Rambus | N13: M321R4GA3PB1-CCPYC | O13: RE32 | P13: 1DPC 6400(16) | Q13: 32.D91.2604210616 | R13: MT2529J01M5T | S13: 02YAVXFS2000010 | T13: Gen6 | U13: SMV_Margin | V13: x8x8 | W13: CX8 | X13: pxp4 | Y13: 0 | Z13: =HYPERLINK("https://hsdes.intel.com/resource/15019304890", "15019304890") | AA13: 3 | AB13: 3 | AC13: 3 | AD13: =ROUND((VALUE(LEFT(SMV_Margin!G5,SEARCH(":",SMV_Margin!G5)-1)) + VALUE(MID(SMV_Margin!G5,SEARCH(":",SMV_Margin!G5)+1,2))/60 + VALUE(RIGHT(SMV_Margin!G5,2))/3600),2) | AE13: PASS | AF13: NA | AG13: NA | AH13: NA | AI13: NA | AJ13: NA | AK13: NA | AL13: NA | AM13: NA | AN13: 1 | AP13: http://10.239.81.58/Xeon/NTA/PCIE/xfusion/unit2-dbgsz11/pxp4.port0_x8/SMV/
A14: 13 | B14: 1S1 | C14: 0 | D14: =IF(C14=0,1,2) | E14: dbgsz11 | F14: xFusion #2 | G14: 02YACYLHS3000001 | H14: 02YABSXFR90008 | I14: ES1/Q9WK | J14: 5795964AD7886700 | L14: Samsung | M14: Rambus | N14: M321R4GA3PB1-CCPYC | O14: RE32 | P14: 1DPC 6400(16) | Q14: 32.D91.2604210616 | R14: MT2529J01M5T | S14: 02YAVXFS2000010 | T14: Gen6 | U14: SMV_Margin | V14: x8x8 | W14: CX8 | X14: pxp4 | Y14: 4 | Z14: =HYPERLINK("https://hsdes.intel.com/resource/15019305093", "15019305093") | AA14: 3 | AB14: 3 | AC14: 3 | AD14: =ROUND((VALUE(LEFT(SMV_Margin!G6,SEARCH(":",SMV_Margin!G6)-1)) + VALUE(MID(SMV_Margin!G6,SEARCH(":",SMV_Margin!G6)+1,2))/60 + VALUE(RIGHT(SMV_Margin!G6,2))/3600),2) | AE14: PASS | AF14: NA | AG14: NA | AH14: NA | AI14: NA | AJ14: NA | AK14: NA | AL14: NA | AM14: NA | AN14: 1 | AP14: http://10.239.81.58/Xeon/NTA/PCIE/xfusion/unit2-dbgsz11/pxp4.port4_x8/SMV/
A15: 14 | B15: 1S1 | C15: 0 | D15: =IF(C15=0,1,2) | E15: dbgsz11 | F15: xFusion #2 | G15: 02YACYLHS3000001 | H15: 02YABSXFR90008 | I15: ES1/Q9WK | J15: 5795964AD7886700 | L15: Samsung | M15: Rambus | N15: M321R4GA3PB1-CCPYC | O15: RE32 | P15: 1DPC 6400(16) | Q15: 32.D91.2604210616 | R15: MT2529J01M5T | S15: 02YAVXFR90000008 | T15: Gen6 | U15: SMV_Margin | V15: x16 | W15: CX8 | X15: pxp9 | Y15: 0 | Z15: =HYPERLINK("https://hsdes.intel.com/resource/15019305366", "15019305366") | AA15: 3 | AB15: 3 | AC15: 3 | AD15: =ROUND((VALUE(LEFT(SMV_Margin!G7,SEARCH(":",SMV_Margin!G7)-1)) + VALUE(MID(SMV_Margin!G7,SEARCH(":",SMV_Margin!G7)+1,2))/60 + VALUE(RIGHT(SMV_Margin!G7,2))/3600),2) | AE15: PASS | AF15: NA | AG15: NA | AH15: NA | AI15: NA | AJ15: NA | AK15: NA | AL15: NA | AM15: NA | AN15: 1 | AP15: http://10.239.81.58/Xeon/NTA/PCIE/xfusion/unit2-dbgsz11/pxp9.port0_x16/SMV/
A16: 15 | B16: 1S1 | C16: 0 | D16: =IF(C16=0,1,2) | E16: dbgsz11 | F16: xFusion #2 | G16: 02YACYLHS3000001 | H16: 02YABSXFR90008 | I16: ES1/Q9WK | J16: 5795964AD7886700 | L16: Samsung | M16: Rambus | N16: M321R4GA3PB1-CCPYC | O16: RE32 | P16: 1DPC 6400(16) | Q16: 32.D91.2604210616 | R16: MT2529J01M5T | S16: 02YAVXFR90000008 | T16: Gen6 | U16: SMV_Margin | V16: x16 | W16: CX8 | X16: pxp11 | Y16: 0 | Z16: =HYPERLINK("https://hsdes.intel.com/resource/15019305355", "15019305355") | AA16: 3 | AB16: 3 | AC16: 3 | AD16: =ROUND((VALUE(LEFT(SMV_Margin!G8,SEARCH(":",SMV_Margin!G8)-1)) + VALUE(MID(SMV_Margin!G8,SEARCH(":",SMV_Margin!G8)+1,2))/60 + VALUE(RIGHT(SMV_Margin!G8,2))/3600),2) | AE16: PASS | AF16: NA | AG16: NA | AH16: NA | AI16: NA | AJ16: NA | AK16: NA | AL16: NA | AM16: NA | AN16: 1 | AP16: http://10.239.81.58/Xeon/NTA/PCIE/xfusion/unit2-dbgsz11/pxp11.port0_x16/SMV/
A17: 16 | B17: 1S1 | C17: 0 | D17: =IF(C17=0,1,2) | E17: dbgsz11 | F17: xFusion #2 | G17: 02YACYLHS3000001 | H17: 02YABSXFR90008 | I17: ES1/Q9WK | J17: 5795964AD7886700 | L17: Samsung | M17: Rambus | N17: M321R4GA3PB1-CCPYC | O17: RE32 | P17: 1DPC 6400(16) | Q17: 32.D91.2604210616 | R17: MT2529J01M5T | S17: 02YAVXFR90000008 | T17: Gen6 | U17: SMV_Margin | V17: x16 | W17: CX8 | X17: pxp12 | Y17: 0 | Z17: =HYPERLINK("https://hsdes.intel.com/resource/15019305350", "15019305350") | AA17: 3 | AB17: 3 | AC17: 3 | AD17: =ROUND((VALUE(LEFT(SMV_Margin!G9,SEARCH(":",SMV_Margin!G9)-1)) + VALUE(MID(SMV_Margin!G9,SEARCH(":",SMV_Margin!G9)+1,2))/60 + VALUE(RIGHT(SMV_Margin!G9,2))/3600),2) | AE17: PASS | AF17: NA | AG17: NA | AH17: NA | AI17: NA | AJ17: NA | AK17: NA | AL17: NA | AM17: NA | AN17: 1 | AP17: http://10.239.81.58/Xeon/NTA/PCIE/xfusion/unit2-dbgsz11/pxp12.port0_x16/SMV/
A18: 17 | B18: 2L1 | C18: 0 | D18: =IF(C18=0,1,2) | E18: dbgsz11 | F18: xFusion #2 | G18: 02YACYLHS3000001 | H18: 02YABSXFR90008 | I18: ES1/Q9WK | J18: 5795964AD7886700 | L18: Samsung | M18: Rambus | N18: M321R4GA3PB1-CCPYC | O18: RE32 | P18: 1DPC 6400(16) | Q18: 32.D91.2604210616 | R18: MT2529J01M5T | S18: 02YAVXFS2000010 | T18: Gen5 | U18: LTSSM | V18: x8x8 | W18: CX8 | X18: pxp1 | Y18: 0 | Z18: 15019294571 | AA18: 1000 | AB18: NA | AC18: NA | AD18: =SUM(LTSSM_Stress!J66:J73)/60 | AE18: PASS | AF18: PASS | AG18: PASS | AH18: PASS | AI18: PASS | AJ18: PASS | AK18: PASS | AL18: PASS | AM18: PASS | AN18: 1 | AP18: http://10.239.81.58/Xeon/NTA/PCIE/xfusion/unit2-dbgsz11/pxp1.port0_x8/LTSSM/
A19: 18 | B19: 2L1 | C19: 0 | D19: =IF(C19=0,1,2) | E19: dbgsz11 | F19: xFusion #2 | G19: 02YACYLHS3000001 | H19: 02YABSXFR90008 | I19: ES1/Q9WK | J19: 5795964AD7886700 | L19: Samsung | M19: Rambus | N19: M321R4GA3PB1-CCPYC | O19: RE32 | P19: 1DPC 6400(16) | Q19: 32.D91.2604210616 | R19: MT2529J01M5T | S19: 02YAVXFS2000010 | T19: Gen5 | U19: LTSSM | V19: x8x8 | W19: CX8 | X19: pxp1 | Y19: 4 | Z19: 15019302203 | AA19: 1000 | AB19: NA | AC19: NA | AD19: =SUM(LTSSM_Stress!J74:J81)/60 | AE19: PASS | AF19: PASS | AG19: PASS | AH19: PASS | AI19: PASS | AJ19: PASS | AK19: PASS | AL19: PASS | AM19: PASS | AN19: 1 | AP19: http://10.239.81.58/Xeon/NTA/PCIE/xfusion/unit2-dbgsz11/pxp1.port4_x8/LTSSM/
A20: 19 | B20: 2L1 | C20: 0 | D20: =IF(C20=0,1,2) | E20: dbgsz11 | F20: xFusion #2 | G20: 02YACYLHS3000001 | H20: 02YABSXFR90008 | I20: ES1/Q9WK | J20: 5795964AD7886700 | L20: Samsung | M20: Rambus | N20: M321R4GA3PB1-CCPYC | O20: RE32 | P20: 1DPC 6400(16) | Q20: 32.D91.2604210616 | R20: MT2529J01M5T | S20: 02YAVXFS2000010/02YAVXFR90000008 | T20: Gen5 | U20: LTSSM | V20: x16 | W20: CX8 | X20: pxp3 | Y20: 0 | Z20: =HYPERLINK("https://hsdes.intel.com/resource/15019302280", "15019302280") | AA20: 1000 | AB20: NA | AC20: NA | AD20: =SUM(LTSSM_Stress!J82:J89)/60 | AE20: PASS | AF20: PASS | AG20: PASS | AH20: PASS | AI20: PASS | AJ20: PASS | AK20: PASS | AL20: PASS | AM20: PASS | AN20: 1 | AP20: http://10.239.81.58/Xeon/NTA/PCIE/xfusion/unit2-dbgsz11/pxp3.port0_x16/LTSSM/ | AQ20: LTSSM use 02YAVXFS2000010 SMV margin use 02YAVXFR90000008
A21: 20 | B21: 2L1 | C21: 0 | D21: =IF(C21=0,1,2) | E21: dbgsz11 | F21: xFusion #2 | G21: 02YACYLHS3000001 | H21: 02YABSXFR90008 | I21: ES1/Q9WK | J21: 5795964AD7886700 | L21: Samsung | M21: Rambus | N21: M321R4GA3PB1-CCPYC | O21: RE32 | P21: 1DPC 6400(16) | Q21: 32.D91.2604210616 | R21: MT2529J01M5T | S21: 02YAVXFS2000010 | T21: Gen5 | U21: LTSSM | V21: x8x8 | W21: CX8 | X21: pxp4 | Y21: 0 | Z21: =HYPERLINK("https://hsdes.intel.com/resource/15019304779", "15019304779") | AA21: 1000 | AB21: NA | AC21: NA | AD21: =SUM(LTSSM_Stress!J90:J97)/60 | AE21: PASS | AF21: PASS | AG21: PASS | AH21: PASS | AI21: PASS | AJ21: PASS | AK21: PASS | AL21: PASS | AM21: PASS | AN21: 1 | AP21: http://10.239.81.58/Xeon/NTA/PCIE/xfusion/unit2-dbgsz11/pxp4.port0_x8/LTSSM/
A22: 21 | B22: 2L1 | C22: 0 | D22: =IF(C22=0,1,2) | E22: dbgsz11 | F22: xFusion #2 | G22: 02YACYLHS3000001 | H22: 02YABSXFR90008 | I22: ES1/Q9WK | J22: 5795964AD7886700 | L22: Samsung | M22: Rambus | N22: M321R4GA3PB1-CCPYC | O22: RE32 | P22: 1DPC 6400(16) | Q22: 32.D91.2604210616 | R22: MT2529J01M5T | S22: 02YAVXFS2000010 | T22: Gen5 | U22: LTSSM | V22: x8x8 | W22: CX8 | X22: pxp4 | Y22: 4 | Z22: =HYPERLINK("https://hsdes.intel.com/resource/15019305686", "15019305686") | AA22: 1000 | AB22: NA | AC22: NA | AD22: =SUM(LTSSM_Stress!J98:J105)/60 | AE22: PASS | AF22: PASS | AG22: PASS | AH22: PASS | AI22: PASS | AJ22: PASS | AK22: PASS | AL22: PASS | AM22: PASS | AN22: 1 | AP22: http://10.239.81.58/Xeon/NTA/PCIE/xfusion/unit2-dbgsz11/pxp4.port4_x8/LTSSM/
A23: 22 | B23: 2L1 | C23: 0 | D23: =IF(C23=0,1,2) | E23: dbgsz11 | F23: xFusion #2 | G23: 02YACYLHS3000001 | H23: 02YABSXFR90008 | I23: ES1/Q9WK | J23: 5795964AD7886700 | L23: Samsung | M23: Rambus | N23: M321R4GA3PB1-CCPYC | O23: RE32 | P23: 1DPC 6400(16) | Q23: 32.D91.2604210616 | R23: MT2529J01M5T | S23: 02YAVXFR90000008 | T23: Gen5 | U23: LTSSM | V23: x16 | W23: CX8 | X23: pxp9 | Y23: 0 | Z23: =HYPERLINK("https://hsdes.intel.com/resource/15019305364", "15019305364") | AA23: 1000 | AB23: NA | AC23: NA | AD23: =SUM(LTSSM_Stress!J106:J113)/60 | AE23: PASS | AF23: PASS | AG23: PASS | AH23: PASS | AI23: PASS | AJ23: PASS | AK23: PASS | AL23: PASS | AM23: PASS | AN23: 1 | AP23: http://10.239.81.58/Xeon/NTA/PCIE/xfusion/unit2-dbgsz11/pxp9.port0_x16/LTSSM/
A24: 23 | B24: 2L1 | C24: 0 | D24: =IF(C24=0,1,2) | E24: dbgsz11 | F24: xFusion #2 | G24: 02YACYLHS3000001 | H24: 02YABSXFR90008 | I24: ES1/Q9WK | J24: 5795964AD7886700 | L24: Samsung | M24: Rambus | N24: M321R4GA3PB1-CCPYC | O24: RE32 | P24: 1DPC 6400(16) | Q24: 32.D91.2604210616 | R24: MT2529J01M5T | S24: 02YAVXFR90000008 | T24: Gen5 | U24: LTSSM | V24: x16 | W24: CX8 | X24: pxp11 | Y24: 0 | Z24: =HYPERLINK("https://hsdes.intel.com/resource/15019305354", "15019305354") | AA24: 1000 | AB24: NA | AC24: NA | AD24: =SUM(LTSSM_Stress!J114:J121)/60 | AE24: PASS | AF24: PASS | AG24: PASS | AH24: PASS | AI24: PASS | AJ24: PASS | AK24: PASS | AL24: PASS | AM24: PASS | AN24: 1 | AP24: http://10.239.81.58/Xeon/NTA/PCIE/xfusion/unit2-dbgsz11/pxp11.port0_x16/LTSSM/
A25: 24 | B25: 2L1 | C25: 0 | D25: =IF(C25=0,1,2) | E25: dbgsz11 | F25: xFusion #2 | G25: 02YACYLHS3000001 | H25: 02YABSXFR90008 | I25: ES1/Q9WK | J25: 5795964AD7886700 | L25: Samsung | M25: Rambus | N25: M321R4GA3PB1-CCPYC | O25: RE32 | P25: 1DPC 6400(16) | Q25: 32.D91.2604210616 | R25: MT2529J01M5T | S25: 02YAVXFR90000008 | T25: Gen5 | U25: LTSSM | V25: x16 | W25: CX8 | X25: pxp12 | Y25: 0 | Z25: =HYPERLINK("https://hsdes.intel.com/resource/15019305349", "15019305349") | AA25: 1000 | AB25: NA | AC25: NA | AD25: =SUM(LTSSM_Stress!J122:J129)/60 | AE25: PASS | AF25: PASS | AG25: PASS | AH25: PASS | AI25: PASS | AJ25: PASS | AK25: PASS | AL25: PASS | AM25: PASS | AN25: 1 | AP25: http://10.239.81.58/Xeon/NTA/PCIE/xfusion/unit2-dbgsz11/pxp12.port0_x16/LTSSM/
A26: 25 | B26: 2S1 | C26: 0 | D26: =IF(C26=0,1,2) | E26: dbgsz11 | F26: xFusion #2 | G26: 02YACYLHS3000001 | H26: 02YABSXFR90008 | I26: ES1/Q9WK | J26: 5795964AD7886700 | L26: Samsung | M26: Rambus | N26: M321R4GA3PB1-CCPYC | O26: RE32 | P26: 1DPC 6400(16) | Q26: 32.D91.2604210616 | R26: MT2529J01M5T | S26: 02YAVXFS2000010 | T26: Gen5 | U26: SMV_Margin | V26: x8x8 | W26: CX8 | X26: pxp1 | Y26: 0 | Z26: 15019294668 | AA26: 3 | AB26: 2 | AC26: 3 | AD26: =ROUND((VALUE(LEFT(SMV_Margin!G10,SEARCH(":",SMV_Margin!G10)-1)) + VALUE(MID(SMV_Margin!G10,SEARCH(":",SMV_Margin!G10)+1,2))/60 + VALUE(RIGHT(SMV_Margin!G10,2))/3600),2) | AE26: PASS | AF26: NA | AG26: NA | AH26: NA | AI26: NA | AJ26: NA | AK26: NA | AL26: NA | AM26: NA | AN26: 1 | AP26: http://10.239.81.58/Xeon/NTA/PCIE/xfusion/unit2-dbgsz11/pxp1.port0_x8/SMV/
A27: 26 | B27: 2S1 | C27: 0 | D27: =IF(C27=0,1,2) | E27: dbgsz11 | F27: xFusion #2 | G27: 02YACYLHS3000001 | H27: 02YABSXFR90008 | I27: ES1/Q9WK | J27: 5795964AD7886700 | L27: Samsung | M27: Rambus | N27: M321R4GA3PB1-CCPYC | O27: RE32 | P27: 1DPC 6400(16) | Q27: 32.D91.2604210616 | R27: MT2529J01M5T | S27: 02YAVXFS2000010 | T27: Gen5 | U27: SMV_Margin | V27: x8x8 | W27: CX8 | X27: pxp1 | Y27: 4 | Z27: 15019302215 | AA27: 3 | AB27: 2 | AC27: 3 | AD27: =ROUND((VALUE(LEFT(SMV_Margin!G11,SEARCH(":",SMV_Margin!G11)-1)) + VALUE(MID(SMV_Margin!G11,SEARCH(":",SMV_Margin!G11)+1,2))/60 + VALUE(RIGHT(SMV_Margin!G11,2))/3600),2) | AE27: PASS | AF27: NA | AG27: NA | AH27: NA | AI27: NA | AJ27: NA | AK27: NA | AL27: NA | AM27: NA | AN27: 1 | AP27: http://10.239.81.58/Xeon/NTA/PCIE/xfusion/unit2-dbgsz11/pxp1.port4_x8/SMV/
A28: 27 | B28: 2S1 | C28: 0 | D28: =IF(C28=0,1,2) | E28: dbgsz11 | F28: xFusion #2 | G28: 02YACYLHS3000001 | H28: 02YABSXFR90008 | I28: ES1/Q9WK | J28: 5795964AD7886700 | L28: Samsung | M28: Rambus | N28: M321R4GA3PB1-CCPYC | O28: RE32 | P28: 1DPC 6400(16) | Q28: 32.D91.2604210616 | R28: MT2529J01M5T | S28: 02YAVXFS2000010/02YAVXFR90000008 | T28: Gen5 | U28: SMV_Margin | V28: x16 | W28: CX8 | X28: pxp3 | Y28: 0 | Z28: =HYPERLINK("https://hsdes.intel.com/resource/15019302282", "15019302282") | AA28: 3 | AB28: 2 | AC28: 3 | AD28: =ROUND((VALUE(LEFT(SMV_Margin!G12,SEARCH(":",SMV_Margin!G12)-1)) + VALUE(MID(SMV_Margin!G12,SEARCH(":",SMV_Margin!G12)+1,2))/60 + VALUE(RIGHT(SMV_Margin!G12,2))/3600),2) | AE28: PASS | AF28: NA | AG28: NA | AH28: NA | AI28: NA | AJ28: NA | AK28: NA | AL28: NA | AM28: NA | AN28: 1 | AP28: http://10.239.81.58/Xeon/NTA/PCIE/xfusion/unit2-dbgsz11/pxp3.port0_x16/SMV/ | AQ28: LTSSM use 02YAVXFS2000010 SMV margin use 02YAVXFR90000008
A29: 28 | B29: 2S1 | C29: 0 | D29: =IF(C29=0,1,2) | E29: dbgsz11 | F29: xFusion #2 | G29: 02YACYLHS3000001 | H29: 02YABSXFR90008 | I29: ES1/Q9WK | J29: 5795964AD7886700 | L29: Samsung | M29: Rambus | N29: M321R4GA3PB1-CCPYC | O29: RE32 | P29: 1DPC 6400(16) | Q29: 32.D91.2604210616 | R29: MT2529J01M5T | S29: 02YAVXFS2000010 | T29: Gen5 | U29: SMV_Margin | V29: x8x8 | W29: CX8 | X29: pxp4 | Y29: 0 | Z29: =HYPERLINK("https://hsdes.intel.com/resource/15019304989", "15019304989") | AA29: 3 | AB29: 2 | AC29: 3 | AD29: =ROUND((VALUE(LEFT(SMV_Margin!G13,SEARCH(":",SMV_Margin!G13)-1)) + VALUE(MID(SMV_Margin!G13,SEARCH(":",SMV_Margin!G13)+1,2))/60 + VALUE(RIGHT(SMV_Margin!G13,2))/3600),2) | AE29: PASS | AF29: NA | AG29: NA | AH29: NA | AI29: NA | AJ29: NA | AK29: NA | AL29: NA | AM29: NA | AN29: 1 | AP29: http://10.239.81.58/Xeon/NTA/PCIE/xfusion/unit2-dbgsz11/pxp4.port0_x8/SMV/
A30: 29 | B30: 2S1 | C30: 0 | D30: =IF(C30=0,1,2) | E30: dbgsz11 | F30: xFusion #2 | G30: 02YACYLHS3000001 | H30: 02YABSXFR90008 | I30: ES1/Q9WK | J30: 5795964AD7886700 | L30: Samsung | M30: Rambus | N30: M321R4GA3PB1-CCPYC | O30: RE32 | P30: 1DPC 6400(16) | Q30: 32.D91.2604210616 | R30: MT2529J01M5T | S30: 02YAVXFS2000010 | T30: Gen5 | U30: SMV_Margin | V30: x8x8 | W30: CX8 | X30: pxp4 | Y30: 4 | Z30: =HYPERLINK("https://hsdes.intel.com/resource/15019305239", "15019305239") | AA30: 3 | AB30: 2 | AC30: 3 | AD30: =ROUND((VALUE(LEFT(SMV_Margin!G14,SEARCH(":",SMV_Margin!G14)-1)) + VALUE(MID(SMV_Margin!G14,SEARCH(":",SMV_Margin!G14)+1,2))/60 + VALUE(RIGHT(SMV_Margin!G14,2))/3600),2) | AE30: PASS | AF30: NA | AG30: NA | AH30: NA | AI30: NA | AJ30: NA | AK30: NA | AL30: NA | AM30: NA | AN30: 1 | AP30: http://10.239.81.58/Xeon/NTA/PCIE/xfusion/unit2-dbgsz11/pxp4.port4_x8/SMV/
A31: 30 | B31: 2S1 | C31: 0 | D31: =IF(C31=0,1,2) | E31: dbgsz11 | F31: xFusion #2 | G31: 02YACYLHS3000001 | H31: 02YABSXFR90008 | I31: ES1/Q9WK | J31: 5795964AD7886700 | L31: Samsung | M31: Rambus | N31: M321R4GA3PB1-CCPYC | O31: RE32 | P31: 1DPC 6400(16) | Q31: 32.D91.2604210616 | R31: MT2529J01M5T | S31: 02YAVXFR90000008 | T31: Gen5 | U31: SMV_Margin | V31: x16 | W31: CX8 | X31: pxp9 | Y31: 0 | Z31: =HYPERLINK("https://hsdes.intel.com/resource/15019305370", "15019305370") | AA31: 3 | AB31: 2 | AC31: 3 | AD31: =ROUND((VALUE(LEFT(SMV_Margin!G15,SEARCH(":",SMV_Margin!G15)-1)) + VALUE(MID(SMV_Margin!G15,SEARCH(":",SMV_Margin!G15)+1,2))/60 + VALUE(RIGHT(SMV_Margin!G15,2))/3600),2) | AE31: PASS | AF31: NA | AG31: NA | AH31: NA | AI31: NA | AJ31: NA | AK31: NA | AL31: NA | AM31: NA | AN31: 1 | AP31: http://10.239.81.58/Xeon/NTA/PCIE/xfusion/unit2-dbgsz11/pxp9.port0_x16/SMV/
A32: 31 | B32: 2S1 | C32: 0 | D32: =IF(C32=0,1,2) | E32: dbgsz11 | F32: xFusion #2 | G32: 02YACYLHS3000001 | H32: 02YABSXFR90008 | I32: ES1/Q9WK | J32: 5795964AD7886700 | L32: Samsung | M32: Rambus | N32: M321R4GA3PB1-CCPYC | O32: RE32 | P32: 1DPC 6400(16) | Q32: 32.D91.2604210616 | R32: MT2529J01M5T | S32: 02YAVXFR90000008 | T32: Gen5 | U32: SMV_Margin | V32: x16 | W32: CX8 | X32: pxp11 | Y32: 0 | Z32: =HYPERLINK("https://hsdes.intel.com/resource/15019305356", "15019305356") | AA32: 3 | AB32: 2 | AC32: 3 | AD32: =ROUND((VALUE(LEFT(SMV_Margin!G16,SEARCH(":",SMV_Margin!G16)-1)) + VALUE(MID(SMV_Margin!G16,SEARCH(":",SMV_Margin!G16)+1,2))/60 + VALUE(RIGHT(SMV_Margin!G16,2))/3600),2) | AE32: PASS | AF32: NA | AG32: NA | AH32: NA | AI32: NA | AJ32: NA | AK32: NA | AL32: NA | AM32: NA | AN32: 1 | AP32: http://10.239.81.58/Xeon/NTA/PCIE/xfusion/unit2-dbgsz11/pxp11.port0_x16/SMV/
A33: 32 | B33: 2S1 | C33: 0 | D33: =IF(C33=0,1,2) | E33: dbgsz11 | F33: xFusion #2 | G33: 02YACYLHS3000001 | H33: 02YABSXFR90008 | I33: ES1/Q9WK | J33: 5795964AD7886700 | L33: Samsung | M33: Rambus | N33: M321R4GA3PB1-CCPYC | O33: RE32 | P33: 1DPC 6400(16) | Q33: 32.D91.2604210616 | R33: MT2529J01M5T | S33: 02YAVXFR90000008 | T33: Gen5 | U33: SMV_Margin | V33: x16 | W33: CX8 | X33: pxp12 | Y33: 0 | Z33: =HYPERLINK("https://hsdes.intel.com/resource/15019305352", "15019305352") | AA33: 3 | AB33: 2 | AC33: 3 | AD33: =ROUND((VALUE(LEFT(SMV_Margin!G17,SEARCH(":",SMV_Margin!G17)-1)) + VALUE(MID(SMV_Margin!G17,SEARCH(":",SMV_Margin!G17)+1,2))/60 + VALUE(RIGHT(SMV_Margin!G17,2))/3600),2) | AE33: PASS | AF33: NA | AG33: NA | AH33: NA | AI33: NA | AJ33: NA | AK33: NA | AL33: NA | AM33: NA | AN33: 1 | AP33: http://10.239.81.58/Xeon/NTA/PCIE/xfusion/unit2-dbgsz11/pxp12.port0_x16/SMV/

Sheet Test_Details-back
A1: 原始序列 | B1: ID | C1: 父 ID | D1: Level | E1: Board | F1: Board Name | G1: PPIN | H1: QDF | I1: Memory P/N | J1: BIOS | K1: BMC | L1: CPLD | M1: Gen# | N1: Test | O1: Bifurcation | P1: PCIE | Q1: Pxpstr | R1: Portno | S1: WO# | T1: iteration | U1: reset | V1: resetType | W1: Test Duration | X1: Result/Margin | Y1: retrain | Z1: speedchange_all | AA1: speedchange_max | AB1: txeqredo | AC1: pml1_disable | AD1: sbr | AE1: link_disable | AF1: pml1_enable | AG1: Failed iterations | AH1: Fail rate | AI1: HSD# | AJ1: Log Link | AK1: Comments
A2: 1 | B2: 1L1 | C2: 0 | D2: =IF(C2=0,1,2) | E2: Intel JNC2 | F2: VAO254600036 | G2: 5772954CF1246B4E | H2: ES1/Q9WJ | I2: M321R4GA3PB1-CCPPC 00CE012332050091C9 | J2: 32D91 | K2: oks-2026.07.2-g43a8af-5fe4f9b | M2: Gen6 | N2: LTSSM | O2: x16 | P2: CX8 | Q2: pxp1 | R2: 0 | T2: 1000 | U2: NA | V2: NA | W2: 0.18084491 | X2: PASS | Y2: PASS | Z2: PASS | AA2: PASS | AB2: PASS | AC2: PASS | AD2: PASS | AE2: PASS | AF2: PASS | AG2: 0 | AH2: =AG2/T2 | AJ2: http://10.239.81.58/Xeon/NTA/PCIE/JNC2-dbgsh83/pxp1/LTSSM_Stress/
A3: 2 | B3: 1L3 | C3: 0 | D3: =IF(C3=0,1,2) | E3: Intel JNC2 | F3: VAO254600036 | G3: 5772954CF1246B4E | H3: ES1/Q9WJ | I3: M321R4GA3PB1-CCPPC 00CE012332050091C9 | J3: 32D91 | K3: oks-2026.07.2-g43a8af-5fe4f9b | M3: Gen6 | N3: LTSSM | O3: x16 | P3: CX8 | Q3: pxp3 | R3: 0 | T3: 1000 | U3: NA | V3: NA | W3: 0.18145833 | X3: PASS | Y3: PASS | Z3: PASS | AA3: PASS | AB3: PASS | AC3: PASS | AD3: PASS | AE3: PASS | AF3: PASS | AG3: 0 | AH3: =AG3/T3 | AJ3: http://10.239.81.58/Xeon/NTA/PCIE/JNC2-dbgsh83/pxp3/LTSSM_Stress/
A4: 3 | B4: 1L4 | C4: 0 | D4: =IF(C4=0,1,2) | E4: Intel JNC2 | F4: VAO254600036 | G4: 57729510C5D400E0 | H4: ES1/Q9WJ | I4: M321R4GA3PB1-CCPPC 00CE012332050091C9 | J4: 32D91 | K4: oks-2026.07.2-g43a8af-5fe4f9b | M4: Gen6 | N4: LTSSM | O4: x16 | P4: CX8 | Q4: pxp4 | R4: 0 | T4: 1000 | U4: NA | V4: NA | W4: 0.18545139 | X4: PASS | Y4: PASS | Z4: PASS | AA4: PASS | AB4: PASS | AC4: PASS | AD4: PASS | AE4: PASS | AF4: PASS | AG4: 0 | AH4: =AG4/T4 | AJ4: http://10.239.81.58/Xeon/NTA/PCIE/JNC2-dbgsh83/pxp4/LTSSM_Stress/
A5: 4 | B5: 1L9 | C5: 0 | D5: =IF(C5=0,1,2) | E5: Intel JNC2 | F5: VAO254600036 | G5: 5772954CF1246B4E | H5: ES1/Q9WJ | I5: M321R4GA3PB1-CCPPC 00CE012332050091C9 | J5: 32D91 | K5: oks-2026.07.2-g43a8af-5fe4f9b | M5: Gen6 | N5: LTSSM | O5: x16 | P5: CX8 | Q5: pxp9 | R5: 0 | T5: 1000 | U5: NA | V5: NA | W5: 0.24822917 | X5: PASS | Y5: PASS | Z5: PASS | AA5: PASS | AB5: PASS | AC5: PASS | AD5: PASS | AE5: PASS | AF5: PASS | AG5: 0 | AH5: =AG5/T5 | AJ5: http://10.239.81.58/Xeon/NTA/PCIE/JNC2-dbgsh83/pxp9/LTSSM_Stress/
A6: 5 | B6: 1L11 | C6: 0 | D6: =IF(C6=0,1,2) | E6: Intel JNC2 | F6: VAO254600036 | G6: 57729510C5D400E0 | H6: ES1/Q9WJ | I6: M321R4GA3PB1-CCPPC 00CE012332050091C9 | J6: 32D91 | K6: oks-2026.07.2-g43a8af-5fe4f9b | M6: Gen6 | N6: LTSSM | O6: x16 | P6: CX8 | Q6: pxp11 | R6: 0 | T6: 1000 | U6: NA | V6: NA | W6: 0.24953704 | X6: FAIL | Y6: PASS | Z6: FAIL | AA6: PASS | AB6: PASS | AC6: PASS | AD6: FAIL | AE6: FAIL | AF6: PASS | AG6: 341 | AH6: =AG6/T6 | AJ6: http://10.239.81.58/Xeon/NTA/PCIE/JNC2-dbgsh83/pxp11/LTSSM_Stress/ | AK6: pxp11.port0 has detected uncorrectable errors: Uncorrectable Bridge Errors LTSSM1 Bridge Errors IBST Bridge Errors
A7: 6 | B7: 1L1 | C7: 0 | D7: =IF(C7=0,1,2) | E7: Intel JNC2 | F7: VAO254600036 | G7: 57729510C5D400E0 | H7: ES1/Q9WJ | I7: M321R4GA3PB1-CCPPC 00CE012332050091C9 | J7: 32D91 | K7: oks-2026.07.2-g43a8af-5fe4f9b | M7: Gen6 | N7: LTSSM | O7: x4x4x4x4 | P7: E1.S | Q7: pxp1 | R7: 0 | T7: 1000 | U7: NA | V7: NA | W7: 0.16547454 | X7: FAIL | Y7: PASS | Z7: PASS | AA7: PASS | AB7: PASS | AC7: PASS | AD7: FAIL | AE7: FAIL | AF7: PASS | AJ7: http://10.239.81.58/Xeon/NTA/PCIE/JNC2-dbgsh83/pxp1_12_x4x4x4x4_E1.S/LTSSM_Stress/
A8: 7 | B8: 1L1 | C8: 0 | D8: =IF(C8=0,1,2) | E8: Intel JNC2 | F8: VAO254600036 | G8: 57729510C5D400E0 | H8: ES1/Q9WJ | I8: M321R4GA3PB1-CCPPC 00CE012332050091C9 | J8: 32D91 | K8: oks-2026.07.2-g43a8af-5fe4f9b | M8: Gen6 | N8: LTSSM | O8: x4x4x4x4 | P8: E1.S | Q8: pxp1 | R8: 2 | T8: 1000 | U8: NA | V8: NA | W8: 0.16554398 | X8: FAIL | Y8: PASS | Z8: PASS | AA8: PASS | AB8: PASS | AC8: PASS | AD8: FAIL | AE8: FAIL | AF8: PASS | AJ8: http://10.239.81.58/Xeon/NTA/PCIE/JNC2-dbgsh83/pxp1_12_x4x4x4x4_E1.S/LTSSM_Stress/
A9: 8 | B9: 1L1 | C9: 0 | D9: =IF(C9=0,1,2) | E9: Intel JNC2 | F9: VAO254600036 | G9: 57729510C5D400E0 | H9: ES1/Q9WJ | I9: M321R4GA3PB1-CCPPC 00CE012332050091C9 | J9: 32D91 | K9: oks-2026.07.2-g43a8af-5fe4f9b | M9: Gen6 | N9: LTSSM | O9: x4x4x4x4 | P9: E1.S | Q9: pxp1 | R9: 4 | T9: 1000 | U9: NA | V9: NA | W9: 0.16584491 | X9: FAIL | Y9: PASS | Z9: PASS | AA9: PASS | AB9: PASS | AC9: PASS | AD9: FAIL | AE9: PASS | AF9: PASS | AJ9: http://10.239.81.58/Xeon/NTA/PCIE/JNC2-dbgsh83/pxp1_12_x4x4x4x4_E1.S/LTSSM_Stress/
A10: 9 | B10: 1L1 | C10: 0 | D10: =IF(C10=0,1,2) | E10: Intel JNC2 | F10: VAO254600036 | G10: 57729510C5D400E0 | H10: ES1/Q9WJ | I10: M321R4GA3PB1-CCPPC 00CE012332050091C9 | J10: 32D91 | K10: oks-2026.07.2-g43a8af-5fe4f9b | M10: Gen6 | N10: LTSSM | O10: x4x4x4x4 | P10: E1.S | Q10: pxp1 | R10: 6 | T10: 1000 | U10: NA | V10: NA | W10: 0.16590278 | X10: FAIL | Y10: PASS | Z10: PASS | AA10: PASS | AB10: PASS | AC10: PASS | AD10: FAIL | AE10: FAIL | AF10: PASS | AJ10: http://10.239.81.58/Xeon/NTA/PCIE/JNC2-dbgsh83/pxp1_12_x4x4x4x4_E1.S/LTSSM_Stress/
A11: 10 | B11: 1L12 | C11: 0 | D11: =IF(C11=0,1,2) | E11: Intel JNC2 | F11: VAO254600036 | G11: 57729510C5D400E0 | H11: ES1/Q9WJ | I11: M321R4GA3PB1-CCPPC 00CE012332050091C9 | J11: 32D91 | K11: oks-2026.07.2-g43a8af-5fe4f9b | M11: Gen6 | N11: LTSSM | O11: x4x4x4x4 | P11: E1.S | Q11: pxp12 | R11: 0 | T11: 1000 | U11: NA | V11: NA | W11: 0.20886574 | X11: FAIL | Y11: PASS | Z11: PASS | AA11: PASS | AB11: PASS | AC11: PASS | AD11: FAIL | AE11: FAIL | AF11: PASS | AG11: 100 | AH11: 0.05 | AJ11: http://10.239.81.58/Xeon/NTA/PCIE/JNC2-dbgsh83/pxp1_12_x4x4x4x4_E1.S/LTSSM_Stress/
A12: 11 | B12: 1L12 | C12: 0 | D12: =IF(C12=0,1,2) | E12: Intel JNC2 | F12: VAO254600036 | G12: 57729510C5D400E0 | H12: ES1/Q9WJ | I12: M321R4GA3PB1-CCPPC 00CE012332050091C9 | J12: 32D91 | K12: oks-2026.07.2-g43a8af-5fe4f9b | M12: Gen6 | N12: LTSSM | O12: x4x4x4x4 | P12: E1.S | Q12: pxp12 | R12: 2 | T12: 1000 | U12: NA | V12: NA | W12: 0.20946759 | X12: FAIL | Y12: PASS | Z12: FAIL | AA12: PASS | AB12: PASS | AC12: FAIL | AD12: FAIL | AE12: FAIL | AF12: PASS | AG12: 159 | AH12: 0.053 | AJ12: http://10.239.81.58/Xeon/NTA/PCIE/JNC2-dbgsh83/pxp1_12_x4x4x4x4_E1.S/LTSSM_Stress/
A13: 12 | B13: 1L12 | C13: 0 | D13: =IF(C13=0,1,2) | E13: Intel JNC2 | F13: VAO254600036 | G13: 57729510C5D400E0 | H13: ES1/Q9WJ | I13: M321R4GA3PB1-CCPPC 00CE012332050091C9 | J13: 32D91 | K13: oks-2026.07.2-g43a8af-5fe4f9b | M13: Gen6 | N13: LTSSM | O13: x4x4x4x4 | P13: E1.S | Q13: pxp12 | R13: 4 | T13: 1000 | U13: NA | V13: NA | W13: 0.20986111 | X13: FAIL | Y13: PASS | Z13: PASS | AA13: PASS | AB13: PASS | AC13: FAIL | AD13: FAIL | AE13: FAIL | AF13: FAIL | AJ13: http://10.239.81.58/Xeon/NTA/PCIE/JNC2-dbgsh83/pxp1_12_x4x4x4x4_E1.S/LTSSM_Stress/
A14: 13 | B14: 1L12 | C14: 0 | D14: =IF(C14=0,1,2) | E14: Intel JNC2 | F14: VAO254600036 | G14: 57729510C5D400E0 | H14: ES1/Q9WJ | I14: M321R4GA3PB1-CCPPC 00CE012332050091C9 | J14: 32D91 | K14: oks-2026.07.2-g43a8af-5fe4f9b | M14: Gen6 | N14: LTSSM | O14: x4x4x4x4 | P14: E1.S | Q14: pxp12 | R14: 6 | T14: 1000 | U14: NA | V14: NA | W14: 0.2097338 | X14: FAIL | Y14: PASS | Z14: PASS | AA14: PASS | AB14: PASS | AC14: FAIL | AD14: FAIL | AE14: FAIL | AF14: PASS | AJ14: http://10.239.81.58/Xeon/NTA/PCIE/JNC2-dbgsh83/pxp1_12_x4x4x4x4_E1.S/LTSSM_Stress/
A15: 14 | B15: 1S1 | C15: 0 | D15: =IF(C15=0,1,2) | E15: Intel JNC2 | F15: VAO254600036 | G15: 57729510C5D400E0 | H15: ES1/Q9WJ | I15: M321R4GA3PB1-CCPPC 00CE012332050091C9 | J15: 32D91 | K15: oks-2026.07.2-g43a8af-5fe4f9b | M15: Gen6 | N15: SMV_Margin | O15: x16 | P15: CX8 | Q15: pxp1 | T15: 3 | U15: 3 | V15: 3 | W15: 0.047372685 | X15: PASS | Y15: NA | Z15: NA | AA15: NA | AB15: NA | AC15: NA | AD15: NA | AE15: NA | AF15: NA | AG15: 0 | AH15: 0 | AJ15: http://10.239.81.58/Xeon/NTA/PCIE/JNC2-dbgsh83/pxp1/SMV_Margin_Test/ | AK15: pxp1.port0 has detected correctable errors
A16: 15 | B16: 1S3 | C16: 0 | D16: =IF(C16=0,1,2) | E16: Intel JNC2 | F16: VAO254600036 | G16: 57729510C5D400E0 | H16: ES1/Q9WJ | I16: M321R4GA3PB1-CCPPC 00CE012332050091C9 | J16: 32D91 | K16: oks-2026.07.2-g43a8af-5fe4f9b | M16: Gen6 | N16: SMV_Margin | O16: x16 | P16: CX8 | Q16: pxp3 | T16: 3 | U16: 3 | V16: 3 | W16: 0.047222222 | X16: PASS | Y16: NA | Z16: NA | AA16: NA | AB16: NA | AC16: NA | AD16: NA | AE16: NA | AF16: NA | AG16: 0 | AH16: 0 | AJ16: http://10.239.81.58/Xeon/NTA/PCIE/JNC2-dbgsh83/pxp3/SMV_Margin_Test/ | AK16: pxp3.port0 has detected correctable errors
A17: 16 | B17: 1S4 | C17: 0 | D17: =IF(C17=0,1,2) | E17: Intel JNC2 | F17: VAO254600036 | G17: 57729510C5D400E0 | H17: ES1/Q9WJ | I17: M321R4GA3PB1-CCPPC 00CE012332050091C9 | J17: 32D91 | K17: oks-2026.07.2-g43a8af-5fe4f9b | M17: Gen6 | N17: SMV_Margin | O17: x16 | P17: CX8 | Q17: pxp4 | T17: 3 | U17: 3 | V17: 3 | W17: 0.047280093 | X17: PASS | Y17: NA | Z17: NA | AA17: NA | AB17: NA | AC17: NA | AD17: NA | AE17: NA | AF17: NA | AG17: 0 | AH17: 0 | AJ17: http://10.239.81.58/Xeon/NTA/PCIE/JNC2-dbgsh83/pxp4/SMV_Margin_Test/ | AK17: pxp4.port0 has detected correctable errors
A18: 17 | B18: 1S9 | C18: 0 | D18: =IF(C18=0,1,2) | E18: Intel JNC2 | F18: VAO254600036 | G18: 57729510C5D400E0 | H18: ES1/Q9WJ | I18: M321R4GA3PB1-CCPPC 00CE012332050091C9 | J18: 32D91 | K18: oks-2026.07.2-g43a8af-5fe4f9b | M18: Gen6 | N18: SMV_Margin | O18: x16 | P18: CX8 | Q18: pxp9 | T18: 3 | U18: 3 | V18: 3 | W18: 0.047881944 | X18: PASS | Y18: NA | Z18: NA | AA18: NA | AB18: NA | AC18: NA | AD18: NA | AE18: NA | AF18: NA | AG18: 0 | AH18: 0 | AJ18: http://10.239.81.58/Xeon/NTA/PCIE/JNC2-dbgsh83/pxp9/SMV_Margin_Test/ | AK18: pxp9.port0 has detected correctable errors
A19: 18 | B19: 1S11 | C19: 0 | D19: =IF(C19=0,1,2) | E19: Intel JNC2 | F19: VAO254600036 | G19: 57729510C5D400E0 | H19: ES1/Q9WJ | I19: M321R4GA3PB1-CCPPC 00CE012332050091C9 | J19: 32D91 | K19: oks-2026.07.2-g43a8af-5fe4f9b | M19: Gen6 | N19: SMV_Margin | O19: x16 | P19: CX8 | Q19: pxp11 | T19: 3 | U19: 3 | V19: 3 | W19: 0.04724537 | X19: PASS | Y19: NA | Z19: NA | AA19: NA | AB19: NA | AC19: NA | AD19: NA | AE19: NA | AF19: NA | AG19: 0 | AH19: 0 | AJ19: http://10.239.81.58/Xeon/NTA/PCIE/JNC2-dbgsh83/pxp11/SMV_Margin_Test/ | AK19: pxp11.port0 has detected correctable errors
A20: 19 | B20: 1S1 | C20: 0 | D20: =IF(C20=0,1,2) | E20: Intel JNC2 | F20: VAO254600036 | G20: 57729510C5D400E0 | H20: ES1/Q9WJ | I20: M321R4GA3PB1-CCPPC 00CE012332050091C9 | J20: 32D91 | K20: oks-2026.07.2-g43a8af-5fe4f9b | M20: Gen6 | N20: SMV_Margin | O20: x4x4x4x4 | P20: E1.S | Q20: pxp1 | R20: 0 | T20: 3 | U20: 3 | V20: 3 | W20: 0.016145833 | X20: PASS | Y20: NA | Z20: NA | AA20: NA | AB20: NA | AC20: NA | AD20: NA | AE20: NA | AF20: NA | AG20: 0 | AH20: 0 | AJ20: http://10.239.81.58/Xeon/NTA/PCIE/JNC2-dbgsh83/pxp1_12_x4x4x4x4_E1.S/SMV_Margin_Test/GEN6/
A21: 20 | B21: 1S1 | C21: 0 | D21: =IF(C21=0,1,2) | E21: Intel JNC2 | F21: VAO254600036 | G21: 57729510C5D400E0 | H21: ES1/Q9WJ | I21: M321R4GA3PB1-CCPPC 00CE012332050091C9 | J21: 32D91 | K21: oks-2026.07.2-g43a8af-5fe4f9b | M21: Gen6 | N21: SMV_Margin | O21: x4x4x4x4 | P21: E1.S | Q21: pxp1 | R21: 2 | T21: 3 | U21: 3 | V21: 3 | W21: 0.016331019 | X21: PASS | Y21: NA | Z21: NA | AA21: NA | AB21: NA | AC21: NA | AD21: NA | AE21: NA | AF21: NA | AG21: 0 | AH21: 0 | AJ21: http://10.239.81.58/Xeon/NTA/PCIE/JNC2-dbgsh83/pxp1_12_x4x4x4x4_E1.S/SMV_Margin_Test/GEN6/
A22: 21 | B22: 1S1 | C22: 0 | D22: =IF(C22=0,1,2) | E22: Intel JNC2 | F22: VAO254600036 | G22: 57729510C5D400E0 | H22: ES1/Q9WJ | I22: M321R4GA3PB1-CCPPC 00CE012332050091C9 | J22: 32D91 | K22: oks-2026.07.2-g43a8af-5fe4f9b | M22: Gen6 | N22: SMV_Margin | O22: x4x4x4x4 | P22: E1.S | Q22: pxp1 | R22: 4 | T22: 3 | U22: 3 | V22: 3 | W22: 0.016354167 | X22: PASS | Y22: NA | Z22: NA | AA22: NA | AB22: NA | AC22: NA | AD22: NA | AE22: NA | AF22: NA | AG22: 0 | AH22: 0 | AJ22: http://10.239.81.58/Xeon/NTA/PCIE/JNC2-dbgsh83/pxp1_12_x4x4x4x4_E1.S/SMV_Margin_Test/GEN6/
A23: 22 | B23: 1S1 | C23: 0 | D23: =IF(C23=0,1,2) | E23: Intel JNC2 | F23: VAO254600036 | G23: 57729510C5D400E0 | H23: ES1/Q9WJ | I23: M321R4GA3PB1-CCPPC 00CE012332050091C9 | J23: 32D91 | K23: oks-2026.07.2-g43a8af-5fe4f9b | M23: Gen6 | N23: SMV_Margin | O23: x4x4x4x4 | P23: E1.S | Q23: pxp1 | R23: 6 | T23: 3 | U23: 3 | V23: 3 | W23: 0.01630787 | X23: PASS | Y23: NA | Z23: NA | AA23: NA | AB23: NA | AC23: NA | AD23: NA | AE23: NA | AF23: NA | AG23: 0 | AH23: 0 | AJ23: http://10.239.81.58/Xeon/NTA/PCIE/JNC2-dbgsh83/pxp1_12_x4x4x4x4_E1.S/SMV_Margin_Test/GEN6/
A24: 23 | B24: 1S12 | C24: 0 | D24: =IF(C24=0,1,2) | E24: Intel JNC2 | F24: VAO254600036 | G24: 57729510C5D400E0 | H24: ES1/Q9WJ | I24: M321R4GA3PB1-CCPPC 00CE012332050091C9 | J24: 32D91 | K24: oks-2026.07.2-g43a8af-5fe4f9b | M24: Gen6 | N24: SMV_Margin | O24: x4x4x4x4 | P24: E1.S | Q24: pxp12 | R24: 0 | T24: 3 | U24: 3 | V24: 3 | W24: 0.016296296 | X24: PASS | Y24: NA | Z24: NA | AA24: NA | AB24: NA | AC24: NA | AD24: NA | AE24: NA | AF24: NA | AG24: 0 | AH24: 0 | AJ24: http://10.239.81.58/Xeon/NTA/PCIE/JNC2-dbgsh83/pxp1_12_x4x4x4x4_E1.S/SMV_Margin_Test/GEN6/
A25: 24 | B25: 1S12 | C25: 0 | D25: =IF(C25=0,1,2) | E25: Intel JNC2 | F25: VAO254600036 | G25: 57729510C5D400E0 | H25: ES1/Q9WJ | I25: M321R4GA3PB1-CCPPC 00CE012332050091C9 | J25: 32D91 | K25: oks-2026.07.2-g43a8af-5fe4f9b | M25: Gen6 | N25: SMV_Margin | O25: x4x4x4x4 | P25: E1.S | Q25: pxp12 | R25: 2 | T25: 3 | U25: 3 | V25: 3 | W25: 0.016481481 | X25: PASS | Y25: NA | Z25: NA | AA25: NA | AB25: NA | AC25: NA | AD25: NA | AE25: NA | AF25: NA | AG25: 0 | AH25: 0 | AJ25: http://10.239.81.58/Xeon/NTA/PCIE/JNC2-dbgsh83/pxp1_12_x4x4x4x4_E1.S/SMV_Margin_Test/GEN6/
A26: 25 | B26: 1S12 | C26: 0 | D26: =IF(C26=0,1,2) | E26: Intel JNC2 | F26: VAO254600036 | G26: 57729510C5D400E0 | H26: ES1/Q9WJ | I26: M321R4GA3PB1-CCPPC 00CE012332050091C9 | J26: 32D91 | K26: oks-2026.07.2-g43a8af-5fe4f9b | M26: Gen6 | N26: SMV_Margin | O26: x4x4x4x4 | P26: E1.S | Q26: pxp12 | R26: 4 | T26: 3 | U26: 3 | V26: 3 | W26: 0.016145833 | X26: PASS | Y26: NA | Z26: NA | AA26: NA | AB26: NA | AC26: NA | AD26: NA | AE26: NA | AF26: NA | AG26: 0 | AH26: 0 | AJ26: http://10.239.81.58/Xeon/NTA/PCIE/JNC2-dbgsh83/pxp1_12_x4x4x4x4_E1.S/SMV_Margin_Test/GEN6/
A27: 26 | B27: 1S12 | C27: 0 | D27: =IF(C27=0,1,2) | E27: Intel JNC2 | F27: VAO254600036 | G27: 57729510C5D400E0 | H27: ES1/Q9WJ | I27: M321R4GA3PB1-CCPPC 00CE012332050091C9 | J27: 32D91 | K27: oks-2026.07.2-g43a8af-5fe4f9b | M27: Gen6 | N27: SMV_Margin | O27: x4x4x4x4 | P27: E1.S | Q27: pxp12 | R27: 6 | T27: 3 | U27: 3 | V27: 3 | W27: 0.016261574 | X27: PASS | Y27: NA | Z27: NA | AA27: NA | AB27: NA | AC27: NA | AD27: NA | AE27: NA | AF27: NA | AG27: 0 | AH27: 0 | AJ27: http://10.239.81.58/Xeon/NTA/PCIE/JNC2-dbgsh83/pxp1_12_x4x4x4x4_E1.S/SMV_Margin_Test/GEN6/
A28: 27 | B28: 2L1 | C28: 0 | D28: =IF(C28=0,1,2) | E28: Intel JNC2 | F28: VAO254600036 | G28: 5772954CF1246B4E | H28: ES1/Q9WJ | I28: M321R4GA3PB1-CCPPC 00CE012332050091C9 | J28: 32D91 | K28: oks-2026.07.2-g43a8af-5fe4f9b | M28: Gen5 | N28: LTSSM | O28: x16 | P28: CX8 | Q28: pxp1 | T28: 1000 | U28: NA | V28: NA | W28: 0.10194444 | X28: FAIL | Y28: PASS | Z28: PASS | AA28: PASS | AB28: PASS | AC28: FAIL | AD28: PASS | AE28: PASS | AF28: FAIL | AG28: 15 | AH28: =AG28/T28 | AJ28: http://10.239.81.58/Xeon/NTA/PCIE/JNC2-dbgsh83/pxp1/LTSSM_Stress/ | AK28: PML1:Correctable error
A29: 28 | B29: 2L3 | C29: 0 | D29: =IF(C29=0,1,2) | E29: Intel JNC2 | F29: VAO254600036 | G29: 5772954CF1246B4E | H29: ES1/Q9WJ | I29: M321R4GA3PB1-CCPPC 00CE012332050091C9 | J29: 32D91 | K29: oks-2026.07.2-g43a8af-5fe4f9b | M29: Gen5 | N29: LTSSM | O29: x16 | P29: CX8 | Q29: pxp3 | T29: 1000 | U29: NA | V29: NA | W29: 0.10179398 | X29: PASS | Y29: PASS | Z29: PASS | AA29: PASS | AB29: PASS | AC29: PASS | AD29: PASS | AE29: PASS | AF29: PASS | AG29: 0 | AH29: =AG29/T29 | AJ29: http://10.239.81.58/Xeon/NTA/PCIE/JNC2-dbgsh83/pxp3/LTSSM_Stress/
A30: 29 | B30: 2L4 | C30: 0 | D30: =IF(C30=0,1,2) | E30: Intel JNC2 | F30: VAO254600036 | G30: 57729510C5D400E0 | H30: ES1/Q9WJ | I30: M321R4GA3PB1-CCPPC 00CE012332050091C9 | J30: 32D91 | K30: oks-2026.07.2-g43a8af-5fe4f9b | M30: Gen5 | N30: LTSSM | O30: x16 | P30: CX8 | Q30: pxp4 | T30: 1000 | U30: NA | V30: NA | W30: 0.10163194 | X30: PASS | Y30: PASS | Z30: PASS | AA30: PASS | AB30: PASS | AC30: PASS | AD30: PASS | AE30: PASS | AF30: PASS | AG30: 0 | AH30: =AG30/T30 | AJ30: http://10.239.81.58/Xeon/NTA/PCIE/JNC2-dbgsh83/pxp4/LTSSM_Stress/
A31: 30 | B31: 2L9 | C31: 0 | D31: =IF(C31=0,1,2) | E31: Intel JNC2 | F31: VAO254600036 | G31: 5772954CF1246B4E | H31: ES1/Q9WJ | I31: M321R4GA3PB1-CCPPC 00CE012332050091C9 | J31: 32D91 | K31: oks-2026.07.2-g43a8af-5fe4f9b | M31: Gen5 | N31: LTSSM | O31: x16 | P31: CX8 | Q31: pxp9 | T31: 1000 | U31: NA | V31: NA | W31: 0.13450231 | X31: PASS | Y31: PASS | Z31: PASS | AA31: PASS | AB31: PASS | AC31: PASS | AD31: PASS | AE31: PASS | AF31: PASS | AG31: 0 | AH31: =AG31/T31 | AJ31: http://10.239.81.58/Xeon/NTA/PCIE/JNC2-dbgsh83/pxp9/LTSSM_Stress/
A32: 31 | B32: 2L11 | C32: 0 | D32: =IF(C32=0,1,2) | E32: Intel JNC2 | F32: VAO254600036 | G32: 57729510C5D400E0 | H32: ES1/Q9WJ | I32: M321R4GA3PB1-CCPPC 00CE012332050091C9 | J32: 32D91 | K32: oks-2026.07.2-g43a8af-5fe4f9b | M32: Gen5 | N32: LTSSM | O32: x16 | P32: CX8 | Q32: pxp11 | T32: 1000 | U32: NA | V32: NA | W32: 0.13393519 | X32: FAIL | Y32: PASS | Z32: FAIL | AA32: PASS | AB32: PASS | AC32: PASS | AD32: FAIL | AE32: FAIL | AF32: PASS | AG32: 273 | AH32: =AG32/T32 | AJ32: http://10.239.81.58/Xeon/NTA/PCIE/JNC2-dbgsh83/pxp11/LTSSM_Stress/ | AK32: pxp11.port0 has detected uncorrectable errors: Uncorrectable Bridge Errors LTSSM1 Bridge Errors IBST Bridge Errors
